Workbook

Sheet Referencias
A1: Grupo | B1: Produto | C1: Qtd Pacote | D1: Vlr Pacote | E1: Unidade | F1: Unitário
A2: Fios | B2: Barroco MultiColor 200g | C2: 200 | D2: 18.99 | E2: gramas | F2: =ROUND(D2/C2,2) -> 0.09
A3: Armarinhos | B3: Bolinha 6,5 | C3: 100 | D3: 104.49 | E3: Unidade | F3: =ROUND(D3/C3,2) -> 1.04
A4: Armarinhos | B4: Cordão Dourado | C4: 50 | D4: 7.49 | E4: m | F4: =ROUND(D4/C4,2) -> 0.15
A5: Fios | B5: Cordão Encerado Settanyl | C5: 100 | D5: 15.9 | E5: m | F5: =ROUND(D5/C5,2) -> 0.16
A6: Armarinhos | B6: Elastico | C6: 10 | D6: 6.9 | E6: m | F6: =ROUND(D6/C6,2) -> 0.69
A7: Fios | B7: Fio Clea 1000 160g | C7: 160 | D7: 16.99 | E7: gramas | F7: =ROUND(D7/C7,2) -> 0.11
A8: Fitas | B8: Fita 7mm | C8: 100 | D8: 9.99 | E8: m | F8: =ROUND(D8/C8,2) -> 0.1
A9: Fitas | B9: Fita cetim | C9: 100 | D9: 12.99 | E9: m | F9: =ROUND(D9/C9,2) -> 0.13
A10: Armarinhos | B10: Ilhos | C10: 100 | D10: 4.89 | E10: Unidade | F10: =ROUND(D10/C10,2) -> 0.05
A11: Armarinhos | B11: Pano de Prato Pé de Galinha | C11: 1 | D11: 4 | E11: Unidade | F11: =ROUND(D11/C11,2) -> 4
A12: Armarinhos | B12: Pano de Prato Atoalhado | C12: 3 | D12: 21.09 | E12: Unidade | F12: =ROUND(D12/C12,2) -> 7.03
A13: Desgaste (Impressora, Encadernadora, Laminadora) | B13: Desgaste Agenda | C13: 1 | D13: 1 | E13: Unidade | F13: =ROUND(D13/C13,2) -> 1
... A32: Laminação e Plastificação | B32: Polaseal A4 Divisórias | C32: 20 | D32: 1.7 | E32: Folha A4 | F32: =ROUND(D32/C32,2) -> 0.09
A33: Laminação e Plastificação | B33: Polaseal marcador 1/4 A4 | C33: =20*4 -> 80 | D33: 1.7 | E33: 1/4 A4 | F33: =ROUND(D33/C33,2) -> 0.02
A34: OffSet 180g | B34: Bolso offset 180gr | C34: 100 | D34: 31.65 | E34: Folha A4 | F34: =ROUND(D34/C34,2) -> 0.32
A35: OffSet 180g | B35: divisórias offset 180gr | C35: 100 | D35: 31.65 | E35: Folha A4 | F35: =ROUND(D35/C35,2) -> 0.32
A36: OffSet 180g | B36: miolo 180g A5 | C36: =100*2 -> 200 | D36: 31.65 | E36: Folha A5 | F36: =ROUND(D36/C36,2) -> 0.16
A37: OffSet 180g | B37: miolo 180gr A4 | C37: 100 | D37: 31.65 | E37: Folha A4 | F37: =ROUND(D37/C37,2) -> 0.32
A38: OffSet 240g | B38: Papel 240g A4 | C38: 100 | D38: 42.2 | E38: Folha A4 | F38: =ROUND(D38/C38,2) -> 0.42
A39: OffSet 75g | B39: miolo 75gr A4 | C39: 500 | D39: 32 | E39: Folha A4 | F39: =ROUND(D39/C39,2) -> 0.06
A40: OffSet 75g | B40: miolo 75gr A5 | C40: =500*2 -> 1000 | D40: 32 | E40: Folha A5 | F40: =ROUND(D40/C40,2) -> 0.03
A41: OffSet 75g | B41: Sulfite 75g A4 | C41: 500 | D41: 32 | E41: Folha A4 | F41: =ROUND(D41/C41,2) -> 0.06
A42: OffSet 75g | B42: Sulfite 75g A5 | C42: =500*2 -> 1000 | D42: 32 | E42: Folha A5 | F42: =ROUND(D42/C42,2) -> 0.03
A43: OffSet 90g | B43: Marcador 90g A6 | C43: =500*4 -> 2000 | D43: 50 | E43: Folha A6 | F43: =ROUND(D43/C43,2) -> 0.03
A44: OffSet 90g | B44: miolo 90gr A4 dobrado no meio | C44: 500 | D44: 50 | E44: Folha A4 | F44: =ROUND(D44/C44,2) -> 0.1
A45: OffSet 90g | B45: miolo 90gr A5 | C45: =500*2 -> 1000 | D45: 50 | E45: Folha A5 | F45: =ROUND(D45/C45,2) -> 0.05
A46: OffSet 90g | B46: miolo 90gr A5 14x18 | C46: =500*2 -> 1000 | D46: 50 | E46: Folha A5 | F46: =ROUND(D46/C46,2) -> 0.05
A47: OffSet Adesivado | B47: Papel guarda 14,5x18 offset adesivo | C47: 40 | D47: 29.8 | E47: Folha A4 | F47: =ROUND(D47/C47,2) -> 0.75
A48: OffSet Adesivado | B48: Papel guarda 15,5x21,5 offset adesivo | C48: 40 | D48: 29.8 | E48: Folha A4 | F48: =ROUND(D48/C48,2) -> 0.75
A49: OffSet Adesivado | B49: Papel guarda 16,5x21,5 offset adesivo | C49: 40 | D49: 29.8 | E49: Folha A4 | F49: =ROUND(D49/C49,2) -> 0.75
A50: OffSet Adesivado | B50: Papel guarda 20x20 offset adesivo | C50: 40 | D50: 29.8 | E50: Folha A4 | F50: =ROUND(D50/C50,2) -> 0.75
A51: OffSet Adesivado | B51: Papel offset adesivo + guarda | C51: 40 | D51: 29.8 | E51: Folha A4 | F51: =ROUND(D51/C51,2) -> 0.75
A52: OffSet Adesivado | B52: Papel offset adesivo A4 | C52: 40 | D52: 29.8 | E52: Folha A4 | F52: =ROUND(D52/C52,2) -> 0.75
A53: Papel Fotográfico | B53: Papel fotografico A4 | C53: 20 | D53: 15.9 | E53: Folha A4 | F53: =ROUND(D53/C53,2) -> 0.8
A54: Papel Kraft | B54: Papel Kraft A4 | C54: 30 | D54: 16.1 | E54: Folha A4 | F54: =ROUND(D54/C54,2) -> 0.54
A55: Papel Kraft | B55: Papel Kraft A5 | C55: =30*2 -> 60 | D55: 16.1 | E55: Folha A5 | F55: =ROUND(D55/C55,2) -> 0.27
A56: Papelão Cinza | B56: Papelão 15,5x21,5+2,5x21,5 | C56: 20 | D56: 29.9 | E56: Folha A4 | F56: =ROUND(D56/C56,2) -> 1.5
A57: Papelão Cinza | B57: Papelão 15x18,5 | C57: 20 | D57: 29.9 | E57: Folha A4 | F57: =ROUND(D57/C57,2) -> 1.5
A58: Papelão Cinza | B58: Papelão 16x22 | C58: 20 | D58: 29.9 | E58: Folha A4 | F58: =ROUND(D58/C58,2) -> 1.5
...

Sheet Mulher25
A1: Mini caderno | D1: 8
A2: =Referencias!B230 -> Papelão 5,5x7,5 | B2: 2 | C2: =Referencias!F230 -> 0.19 | D2: =B2*C2 -> 0.38
A3: =Referencias!B231 -> Papel fotografico 8,5x10,5 | B3: 2 | C3: =Referencias!F231 -> 0.2 | D3: =B3*C3 -> 0.4
A4: =Referencias!B31 -> bopp | B4: 0.08 | C4: =Referencias!F31 -> 0.45 | D4: =B4*C4 -> 0.036
A5: =Referencias!B232 -> Papel guarda 5x7 offset adesivo | B5: 2 | C5: =Referencias!F232 -> 0.19 | D5: =B5*C5 -> 0.38
A6: =Referencias!B233 -> miolo 75gr 5x7 | B6: 70 | C6: =Referencias!F233 -> 0.01 | D6: =B6*C6 -> 0.7
A7: =Referencias!B69 -> Espiral 20mm | B7: 0.17 | C7: =Referencias!F69 -> 0.64 | D7: =B7*C7 -> 0.1088
A8: =Referencias!B22 -> Impressao Capa A4 | B8: 1 | C8: =Referencias!F22 -> 0.5 | D8: =B8*C8 -> 0.5
A9: =Referencias!B62 -> Frete | C9: =Referencias!F62 -> 0 | D9: =B9*C9 -> 0
A10: =Referencias!B14 -> Desgaste Bloquinho/Outros | B10: 1 | C10: =Referencias!F14 -> 0.5 | D10: =B10*C10 -> 0.5
A11: =Referencias!B17 -> Embalagem Padrão | B11: 1 | C11: =Referencias!F17 -> 1.5 | D11: =B11*C11 -> 1.5
A12: Custo | D12: =SUM(D2:D11) -> 4.5048
A13: Margem | B13: 0.55 | C13: =D12*B13 -> 2.47764 | D13: =D12+C13 -> 6.98244
A14: Pesquisa
A15: Valor | D15: 10
A17: Pirulito Personalizado | D17: 2
A18: =Referencias!B236 -> Pirulito Florestal Coração Vermelho | B18: 1 | C18: =Referencias!F236 -> 0.18 | D18: =B18*C18 -> 0.18
A19: =Referencias!B111 -> Card OffSet 180gr | B19: 1 | C19: =Referencias!F111 -> 0.05 | D19: =B19*C19 -> 0.05
A20: =Referencias!B112 -> Impressao Card | B20: 1 | C20: =Referencias!F112 -> 0.08 | D20: =B20*C20 -> 0.08
A21: =Referencias!B62 -> Frete | C21: =Referencias!F62 -> 0 | D21: =B21*C21 -> 0
A22: =Referencias!B14 -> Desgaste Bloquinho/Outros | B22: 1 | C22: =Referencias!F14 -> 0.5 | D22: =B22*C22 -> 0.5
A23: =Referencias!B107 -> Embalagem Atacado | B23: 1 | C23: =Referencias!F107 -> 0.5 | D23: =B23*C23 -> 0.5
A24: Custo | D24: =SUM(D18:D23) -> 1.31
A25: Margem | B25: 0.55 | C25: =D24*B25 -> 0.7205 | D25: =D24+C25 -> 2.0305
A26: Pesquisa
A27: Valor | D27: 2.5

Sheet VoltaAulas25
A1: Planner Viagem
A2: =Referencias!B58 -> Papelão 16x22 | B2: 2 | C2: =Referencias!F58 -> 1.5 | D2: =B2*C2 -> 3
A3: =Referencias!B53 -> Papel fotografico A4 | B3: 2 | C3: =Referencias!F53 -> 0.8 | D3: =B3*C3 -> 1.6
A4: =Referencias!B31 -> bopp | B4: 0.6 | C4: =Referencias!F31 -> 0.45 | D4: =B4*C4 -> 0.27
A5: =Referencias!B48 -> Papel guarda 15,5x21,5 offset adesivo | B5: 2 | C5: =Referencias!F48 -> 0.75 | D5: =B5*C5 -> 1.5
A6: =Referencias!B45 -> miolo 90gr A5 | B6: 32 | C6: =Referencias!F45 -> 0.05 | D6: =B6*C6 -> 1.6
A7: =Referencias!B215 -> Color plus metalico Aspen 120g A4 | B7: 1 | C7: =Referencias!F215 -> 0.7 | D7: =B7*C7 -> 0.7
A8: =Referencias!B35 -> divisórias offset 180gr | B8: 4 | C8: =Referencias!F35 -> 0.32 | D8: =B8*C8 -> 1.28
A9: =Referencias!B32 -> Polaseal A4 Divisórias | B9: 4 | C9: =Referencias!F32 -> 0.09 | D9: =B9*C9 -> 0.36
A10: =Referencias!B19 -> Espiral 29mm | B10: 1 | C10: =Referencias!F19 -> 1.83 | D10: =B10*C10 -> 1.83
A11: =Referencias!B22 -> Impressao Capa A4 | B11: 2 | C11: =Referencias!F22 -> 0.5 | D11: =B11*C11 -> 1
A12: =Referencias!B64 -> Impressao Divisória A4 | B12: 4 | C12: =Referencias!F64 -> 1 | D12: =B12*C12 -> 4
A13: =Referencias!B29 -> Impressao Miolo Frente Verso A5 | B13: 32 | C13: =Referencias!F29 -> 0.06 | D13: =B13*C13 -> 1.92
A14: =Referencias!B62 -> Frete | C14: =Referencias!F62 -> 0 | D14: =B14*C14 -> 0
A15: =Referencias!B16 -> Desgaste Planner/Album/Caderno Universitario | B15: 1 | C15: =Referencias!F16 -> 3 | D15: =B15*C15 -> 3
A16: =Referencias!B17 -> Embalagem Padrão | B16: 1 | C16: =Referencias!F17 -> 1.5 | D16: =B16*C16 -> 1.5
A17: Custo | D17: =SUM(D2:D16) -> 23.56
A18: Margem | B18: 0.55 | C18: =D17*B18 -> 12.958 | D18: =D17+C18 -> 36.518
A19: Pesquisa | D19: =B19*C19 -> 0
A20: Valor | D20: =B20*C20 -> 0
A23: Diário de Leitura | D23: 50
A24: =Referencias!B58 -> Papelão 16x22 | B24: 2 | C24: =Referencias!F58 -> 1.5 | D24: =B24*C24 -> 3
A25: =Referencias!B53 -> Papel fotografico A4 | B25: 2 | C25: =Referencias!F53 -> 0.8 | D25: =B25*C25 -> 1.6
A26: =Referencias!B31 -> bopp | B26: =0.3*2 -> 0.6 | C26: =Referencias!F31 -> 0.45 | D26: =B26*C26 -> 0.27
A27: =Referencias!B48 -> Papel guarda 15,5x21,5 offset adesivo | B27: 2 | C27: =Referencias!F48 -> 0.75 | D27: =B27*C27 -> 1.5
A28: =Referencias!B45 -> miolo 90gr A5 | B28: 100 | C28: =Referencias!F45 -> 0.05 | D28: =B28*C28 -> 5
A29: =Referencias!B215 -> Color plus metalico Aspen 120g A4 | B29: 1 | C29: =Referencias!F215 -> 0.7 | D29: =B29*C29 -> 0.7
A30: =Referencias!B19 -> Espiral 29mm | B30: 1 | C30: =Referencias!F19 -> 1.83 | D30: =B30*C30 -> 1.83
A31: =Referencias!B22 -> Impressao Capa A4 | B31: 2 | C31: =Referencias!F22 -> 0.5 | D31: =B31*C31 -> 1
A32: =Referencias!B29 -> Impressao Miolo Frente Verso A5 | B32: 100 | C32: =Referencias!F29 -> 0.06 | D32: =B32*C32 -> 6
A33: =Referencias!B62 -> Frete | C33: =Referencias!F62 -> 0 | D33: =B33*C33 -> 0
A34: =Referencias!B15 -> Desgaste Caderno A5 | B34: 1 | C34: =Referencias!F15 -> 2 | D34: =B34*C34 -> 2
A35: =Referencias!B17 -> Embalagem Padrão | B35: 1 | C35: =Referencias!F17 -> 1.5 | D35: =B35*C35 -> 1.5
A36: Custo | D36: =SUM(D24:D35) -> 24.4
A37: Margem | B37: 0.55 | C37: =D36*B37 -> 13.42 | D37: =D36+C37 -> 37.82
A38: Pesquisa | B38: Elo 7 | C38: Elo 7 - 111p
A39: Valor | B39: 68 | C39: 85 | D39: 50
A41: Agenda Escolar 1 dia | D41: 45
A42: =Referencias!B58 -> Papelão 16x22 | B42: 2 | C42: =Referencias!F58 -> 1.5 | D42: =B42*C42 -> 3
A43: =Referencias!B53 -> Papel fotografico A4 | B43: 2 | C43: =Referencias!F53 -> 0.8 | D43: =B43*C43 -> 1.6
...

Sheet Coleção25
A1: Agenda 1 dia datada | D1: 79.9
A2: =Referencias!B58 -> Papelão 16x22 | B2: 2 | C2: =Referencias!F58 -> 1.5 | D2: =B2*C2 -> 3
A3: =Referencias!B53 -> Papel fotografico A4 | B3: 2 | C3: =Referencias!F53 -> 0.8 | D3: =B3*C3 -> 1.6
A4: =Referencias!B31 -> bopp | B4: =0.3*2 -> 0.6 | C4: =Referencias!F31 -> 0.45 | D4: =B4*C4 -> 0.27
A5: =Referencias!B48 -> Papel guarda 15,5x21,5 offset adesivo | B5: 2 | C5: =Referencias!F48 -> 0.75 | D5: =B5*C5 -> 1.5
A6: =Referencias!B40 -> miolo 75gr A5 | B6: 204 | C6: =Referencias!F40 -> 0.03 | D6: =B6*C6 -> 6.12
A7: =Referencias!B215 -> Color plus metalico Aspen 120g A4 | B7: 1 | C7: =Referencias!F215 -> 0.7 | D7: =B7*C7 -> 0.7
A8: =Referencias!B120 -> Espiral 33mm plastico | B8: 1 | C8: =Referencias!F120 -> 2.48 | D8: =B8*C8 -> 2.48
A9: =Referencias!B22 -> Impressao Capa A4 | B9: 2 | C9: =Referencias!F22 -> 0.5 | D9: =B9*C9 -> 1
A10: =Referencias!B29 -> Impressao Miolo Frente Verso A5 | B10: 204 | C10: =Referencias!F29 -> 0.06 | D10: =B10*C10 -> 12.24
A11: =Referencias!B62 -> Frete | C11: =Referencias!F62 -> 0 | D11: =B11*C11 -> 0
A12: =Referencias!B13 -> Desgaste Agenda | B12: 1 | C12: =Referencias!F13 -> 1 | D12: =B12*C12 -> 1
A13: =Referencias!B17 -> Embalagem Padrão | B13: 1 | C13: =Referencias!F17 -> 1.5 | D13: =B13*C13 -> 1.5
A14: Custo | D14: =SUM(D2:D13) -> 31.41
A15: Margem | B15: 0.55 | C15: =D14*B15 -> 17.2755 | D15: =D14+C15 -> 48.6855
A16: Pesquisa | B16: praper | C16: mp
A17: Valor | B17: 69 | C17: 75 | D17: 89.9
A19: Agenda 2 dias datada | D19: 55.9
A20: =Referencias!B57 -> Papelão 15x18,5 | B20: 2 | C20: =Referencias!F57 -> 1.5 | D20: =B20*C20 -> 3
A21: =Referencias!B53 -> Papel fotografico A4 | B21: 2 | C21: =Referencias!F53 -> 0.8 | D21: =B21*C21 -> 1.6
A22: =Referencias!B31 -> bopp | B22: =0.3*2 -> 0.6 | C22: =Referencias!F31 -> 0.45 | D22: =B22*C22 -> 0.27
A23: =Referencias!B47 -> Papel guarda 14,5x18 offset adesivo | B23: 2 | C23: =Referencias!F47 -> 0.75 | D23: =B23*C23 -> 1.5
A24: =Referencias!B46 -> miolo 90gr A5 14x18 | B24: 114 | C24: =Referencias!F46 -> 0.05 | D24: =B24*C24 -> 5.7
A25: =Referencias!B215 -> Color plus metalico Aspen 120g A4 | B25: 1 | C25: =Referencias!F215 -> 0.7 | D25: =B25*C25 -> 0.7
A26: =Referencias!B19 -> Espiral 29mm | B26: 1 | C26: =Referencias!F19 -> 1.83 | D26: =B26*C26 -> 1.83
A27: =Referencias!B22 -> Impressao Capa A4 | B27: 2 | C27: =Referencias!F22 -> 0.5 | D27: =B27*C27 -> 1
A28: =Referencias!B29 -> Impressao Miolo Frente Verso A5 | B28: 114 | C28: =Referencias!F29 -> 0.06 | D28: =B28*C28 -> 6.84
A29: =Referencias!B62 -> Frete | C29: =Referencias!F62 -> 0 | D29: =B29*C29 -> 0
A30: =Referencias!B13 -> Desgaste Agenda | B30: 1 | C30: =Referencias!F13 -> 1 | D30: =B30*C30 -> 1
A31: =Referencias!B17 -> Embalagem Padrão | B31: 1 | C31: =Referencias!F17 -> 1.5 | D31: =B31*C31 -> 1.5
A32: Custo | D32: =SUM(D20:D31) -> 24.94
A33: Margem | B33: 0.55 | C33: =D32*B33 -> 13.717 | D33: =D32+C33 -> 38.657
A34: Pesquisa | B34: praper | C34: mp
A35: Valor | B35: 54.9 | C35: 59 | D35: 65.9
A37: Agenda Agendamento | D37: 85.9
A38: =Referencias!B58 -> Papelão 16x22 | B38: 2 | C38: =Referencias!F58 -> 1.5 | D38: =B38*C38 -> 3
A39: =Referencias!B53 -> Papel fotografico A4 | B39: 2 | C39: =Referencias!F53 -> 0.8 | D39: =B39*C39 -> 1.6
A40: =Referencias!B31 -> bopp | B40: =0.3*2 -> 0.6 | C40: =Referencias!F31 -> 0.45 | D40: =B40*C40 -> 0.27
A41: =Referencias!B48 -> Papel guarda 15,5x21,5 offset adesivo | B41: 2 | C41: =Referencias!F48 -> 0.75 | D41: =B41*C41 -> 1.5
A42: =Referencias!B40 -> miolo 75gr A5 | B42: 209 | C42: =Referencias!F40 -> 0.03 | D42: =B42*C42 -> 6.27
...

Sheet Dininha
A1: Jogo da Memória | D1: 15
A2: =Referencias!B65 -> Papelão A4 | B2: 1 | C2: =Referencias!F65 -> 1.5 | D2: =B2*C2 -> 1.5
A3: =Referencias!B53 -> Papel fotografico A4 | B3: 1 | C3: =Referencias!F53 -> 0.8 | D3: =B3*C3 -> 0.8
A4: =Referencias!B31 -> bopp | B4: 0.3 | C4: =Referencias!F31 -> 0.45 | D4: =B4*C4 -> 0.135
A5: =Referencias!B52 -> Papel offset adesivo A4 | B5: 1 | C5: =Referencias!F52 -> 0.75 | D5: =B5*C5 -> 0.75
A6: =Referencias!B38 -> Papel 240g A4 | B6: 1 | C6: =Referencias!F38 -> 0.42 | D6: =B6*C6 -> 0.42
A7: =Referencias!B22 -> Impressao Capa A4 | B7: 4 | C7: =Referencias!F22 -> 0.5 | D7: =B7*C7 -> 2
A8: =Referencias!B62 -> Frete | C8: =Referencias!F62 -> 0 | D8: =B8*C8 -> 0
A9: =Referencias!B14 -> Desgaste Bloquinho/Outros | B9: 1 | C9: =Referencias!F14 -> 0.5 | D9: =B9*C9 -> 0.5
A10: =Referencias!B17 -> Embalagem Padrão | B10: 1 | C10: =Referencias!F17 -> 1.5 | D10: =B10*C10 -> 1.5
A11: Custo | D11: =SUM(D2:D10) -> 7.605
A12: Margem | B12: 0.55 | C12: =D11*B12 -> 4.18275 | D12: =D11+C12 -> 11.78775
A13: Pesquisa
A14: Valor | D14: 15

Sheet Kraft
A1: Bloco Kraft 10x10 bordado espiral pautado | D1: 10
A2: =Referencias!B196 -> Papel Kraft 10,5x9,5 | B2: 2 | C2: =Referencias!F196 -> 0.09 | D2: =B2*C2 -> 0.18
A3: =Referencias!B197 -> Sulfite 90gr 9x9 | B3: 50 | C3: =Referencias!F197 -> 0.03 | D3: =B3*C3 -> 1.5
A4: =Referencias!B199 -> Espiral 14mm | B4: 0.3 | C4: =Referencias!F199 -> 0.42 | D4: =B4*C4 -> 0.126
A5: =Referencias!B198 -> Impressao Miolo Frente Verso 9x9 | B5: 50 | C5: =Referencias!F198 -> 0.02 | D5: =B5*C5 -> 1
A6: =Referencias!B88 -> Linha Circulo Maxi Mouline | B6: 2 | C6: =Referencias!F88 -> 0.18 | D6: =B6*C6 -> 0.36
A7: =Referencias!B62 -> Frete | C7: =Referencias!F62 -> 0 | D7: =B7*C7 -> 0
A8: =Referencias!B14 -> Desgaste Bloquinho/Outros | B8: 1 | C8: =Referencias!F14 -> 0.5 | D8: =B8*C8 -> 0.5
A9: =Referencias!B17 -> Embalagem Padrão | B9: 1 | C9: =Referencias!F17 -> 1.5 | D9: =B9*C9 -> 1.5
A10: Custo | D10: =SUM(D2:D9) -> 5.166
A11: Margem | B11: 0.55 | C11: =D10*B11 -> 2.8413 | D11: =D10+C11 -> 8.0073
A12: Pesquisa | B12: Feito Folhas
A13: Valor | B13: 20 | D13: 10
A15: Caderno Kraft A6 bordado | D15: 20
A16: =Referencias!B55 -> Papel Kraft A5 | B16: 1 | C16: =Referencias!F55 -> 0.27 | D16: =B16*C16 -> 0.27
A17: =Referencias!B42 -> Sulfite 75g A5 | B17: 25 | C17: =Referencias!F42 -> 0.03 | D17: =B17*C17 -> 0.75
A18: =Referencias!B5 -> Cordão Encerado Settanyl | B18: 0.6 | C18: =Referencias!F5 -> 0.16 | D18: =B18*C18 -> 0.096
A19: =Referencias!B88 -> Linha Circulo Maxi Mouline | B19: 2 | C19: =Referencias!F88 -> 0.18 | D19: =B19*C19 -> 0.36
A20: =Referencias!B62 -> Frete | C20: =Referencias!F62 -> 0 | D20: =B20*C20 -> 0
A21: =Referencias!B15 -> Desgaste Caderno A5 | B21: 1 | C21: =Referencias!F15 -> 2 | D21: =B21*C21 -> 2
A22: =Referencias!B17 -> Embalagem Padrão | B22: 1 | C22: =Referencias!F17 -> 1.5 | D22: =B22*C22 -> 1.5
A23: Custo | D23: =SUM(D16:D22) -> 4.976
A24: Margem | B24: 0.55 | C24: =D23*B24 -> 2.7368 | D24: =D23+C24 -> 7.7128
A25: Pesquisa | B25: Feito Folhas
A26: Valor | B26: 20 | D26: 20
A28: Caderno Kraft A5 bordado | D28: 25
A29: =Referencias!B54 -> Papel Kraft A4 | B29: 1 | C29: =Referencias!F54 -> 0.54 | D29: =B29*C29 -> 0.54
A30: =Referencias!B41 -> Sulfite 75g A4 | B30: 30 | C30: =Referencias!F41 -> 0.06 | D30: =B30*C30 -> 1.8
A31: =Referencias!B5 -> Cordão Encerado Settanyl | B31: 1.2 | C31: =Referencias!F5 -> 0.16 | D31: =B31*C31 -> 0.192
A32: =Referencias!B88 -> Linha Circulo Maxi Mouline | B32: 4 | C32: =Referencias!F88 -> 0.18 | D32: =B32*C32 -> 0.72
A33: =Referencias!B62 -> Frete | C33: =Referencias!F62 -> 0 | D33: =B33*C33 -> 0
A34: =Referencias!B15 -> Desgaste Caderno A5 | B34: 1 | C34: =Referencias!F15 -> 2 | D34: =B34*C34 -> 2
A35: =Referencias!B17 -> Embalagem Padrão | B35: 1 | C35: =Referencias!F17 -> 1.5 | D35: =B35*C35 -> 1.5
A36: Custo | D36: =SUM(D29:D35) -> 6.752
A37: Margem | B37: 0.55 | C37: =D36*B37 -> 3.7136 | D37: =D36+C37 -> 10.4656
A38: Pesquisa | B38: Feito Folhas
A39: Valor | B39: 35 | D39: 25
A41: Planner Kraft A5 bordado | D41: 30
A42: =Referencias!B54 -> Papel Kraft A4 | B42: 1 | C42: =Referencias!F54 -> 0.54 | D42: =B42*C42 -> 0.54
A43: =Referencias!B41 -> Sulfite 75g A4 | B43: 27 | C43: =Referencias!F41 -> 0.06 | D43: =B43*C43 -> 1.62
...

Sheet Couro
A1: Caderno Amor | D1: 50
A2: =Referencias!B206 -> Couro 16 cm x 11 cm | B2: 40 | C2: =Referencias!F206 -> 0.02 | D2: =B2*C2 -> 0.8
A3: =Referencias!B207 -> Couro 9 cm x 2 cm | B3: 3 | C3: =Referencias!F207 -> 0.02 | D3: =B3*C3 -> 0.06
A4: =Referencias!B144 -> Papel Kraft A6 | B4: 2 | C4: =Referencias!F144 -> 0.13 | D4: =B4*C4 -> 0.26
A5: =Referencias!B205 -> Pólen Bold - 90 g/m2 - A5 | B5: 42 | C5: =Referencias!F205 -> 0.07 | D5: =B5*C5 -> 2.94
A6: =Referencias!B5 -> Cordão Encerado Settanyl | B6: 2 | C6: =Referencias!F5 -> 0.16 | D6: =B6*C6 -> 0.32
A7: =Referencias!B94 -> Cola Branca 1kg | B7: 40 | C7: =Referencias!F88 -> 0.18 | D7: =B7*C7 -> 7.2
A8: =Referencias!B62 -> Frete | C8: =Referencias!F62 -> 0 | D8: =B8*C8 -> 0
A9: =Referencias!B14 -> Desgaste Bloquinho/Outros | B9: 1 | C9: =Referencias!F14 -> 0.5 | D9: =B9*C9 -> 0.5
A10: =Referencias!B17 -> Embalagem Padrão | B10: 1 | C10: =Referencias!F17 -> 1.5 | D10: =B10*C10 -> 1.5
A11: Custo | D11: =SUM(D2:D10) -> 13.58
A12: Margem | B12: 0.55 | C12: =D11*B12 -> 7.469 | D12: =D11+C12 -> 21.049
A13: Pesquisa | B13: Te
A14: Valor | B14: 50 | C14: 80 | D14: 50
A16: Caderno Leveza | D16: 45
A17: =Referencias!B208 -> Couro 15 cm x 28 cm | B17: 20 | C17: =Referencias!F208 -> 0.02 | D17: =B17*C17 -> 0.4
A18: =Referencias!B209 -> Couro 1,5 cm x 30 cm | B18: 9 | C18: =Referencias!F209 -> 0.02 | D18: =B18*C18 -> 0.18
A19: =Referencias!B210 -> Puxador De Metal Carrapeta 7mmx5mm | B19: 1 | C19: =Referencias!F210 -> 3.3 | D19: =B19*C19 -> 3.3
A20: =Referencias!B205 -> Pólen Bold - 90 g/m2 - A5 | B20: 30 | C20: =Referencias!F205 -> 0.07 | D20: =B20*C20 -> 2.1
A21: =Referencias!B5 -> Cordão Encerado Settanyl | B21: 0.6 | C21: =Referencias!F5 -> 0.16 | D21: =B21*C21 -> 0.096
A22: =Referencias!B94 -> Cola Branca 1kg | B22: 10 | C22: =Referencias!F94 -> 0.04 | D22: =B22*C22 -> 0.4
A23: =Referencias!B62 -> Frete | C23: =Referencias!F62 -> 0 | D23: =B23*C23 -> 0
A24: =Referencias!B14 -> Desgaste Bloquinho/Outros | B24: 1 | C24: =Referencias!F14 -> 0.5 | D24: =B24*C24 -> 0.5
A25: =Referencias!B17 -> Embalagem Padrão | B25: 1 | C25: =Referencias!F17 -> 1.5 | D25: =B25*C25 -> 1.5
A26: Custo | D26: =SUM(D17:D25) -> 8.476
A27: Margem | B27: 0.55 | C27: =D26*B27 -> 4.6618 | D27: =D26+C27 -> 13.1378
A28: Pesquisa | B28: Te
A29: Valor⁴ | B29: 50 | C29: 80 | D29: 45
A31: Caderno Liberdade | D31: 55
A32: =Referencias!B211 -> Couro 15 cm x 32 cm | B32: 38 | C32: =Referencias!F211 -> 0.02 | D32: =B32*C32 -> 0.76
A33: =Referencias!B212 -> Couro 15 cm x 3,5 cm | B33: 12 | C33: =Referencias!F212 -> 0.02 | D33: =B33*C33 -> 0.24
A34: =Referencias!B213 -> Couro 15 cm x 9 cm | B34: 10 | C34: =Referencias!F213 -> 0.02 | D34: =B34*C34 -> 0.2
A35: =Referencias!B205 -> Pólen Bold - 90 g/m2 - A5 | B35: 42 | C35: =Referencias!F205 -> 0.07 | D35: =B35*C35 -> 2.94
A36: =Referencias!B214 -> Ímã Neodímio Ø 20x1 mm N35 | B36: 2 | C36: =Referencias!F214 -> 2.87 | D36: =B36*C36 -> 5.74
A37: =Referencias!B5 -> Cordão Encerado Settanyl | B37: 2.1 | C37: =Referencias!F5 -> 0.16 | D37: =B37*C37 -> 0.336
A38: =Referencias!B94 -> Cola Branca 1kg | B38: 20 | C38: =Referencias!F94 -> 0.04 | D38: =B38*C38 -> 0.8
A39: =Referencias!B62 -> Frete | C39: =Referencias!F62 -> 0 | D39: =B39*C39 -> 0
A40: =Referencias!B14 -> Desgaste Bloquinho/Outros | B40: 1 | C40: =Referencias!F14 -> 0.5 | D40: =B40*C40 -> 0.5
A41: =Referencias!B17 -> Embalagem Padrão | B41: 1 | C41: =Referencias!F17 -> 1.5 | D41: =B41*C41 -> 1.5
A42: Custo | D42: =SUM(D32:D41) -> 13.016
...

Sheet Crochê
A1: Descanso de Panela em Croche Malha - Quadrado | D1: 15
A2: =Referencias!B202 -> Fio de Malha Euroroma 140m | B2: 140 | C2: =Referencias!F202 -> 0.02 | D2: =B2*C2 -> 2.8
A3: =Referencias!B62 -> Frete | C3: =Referencias!F62 -> 0 | D3: =B3*C3 -> 0
A4: =Referencias!B14 -> Desgaste Bloquinho/Outros | B4: 1 | C4: =Referencias!F14 -> 0.5 | D4: =B4*C4 -> 0.5
A5: =Referencias!B17 -> Embalagem Padrão | B5: 1 | C5: =Referencias!F17 -> 1.5 | D5: =B5*C5 -> 1.5
A6: Custo | D6: =SUM(D2:D5) -> 4.8
A7: Margem | B7: 0.55 | C7: =D6*B7 -> 2.64 | D7: =D6+C7 -> 7.44
A8: Pesquisa
A9: Valor | D9: 15
A11: Descanso de Panela em Croche Malha - Flor | D11: 15
A12: =Referencias!B202 -> Fio de Malha Euroroma 140m | B12: 140 | C12: =Referencias!F202 -> 0.02 | D12: =B12*C12 -> 2.8
A13: =Referencias!B62 -> Frete | C13: =Referencias!F62 -> 0 | D13: =B13*C13 -> 0
A14: =Referencias!B14 -> Desgaste Bloquinho/Outros | B14: 1 | C14: =Referencias!F14 -> 0.5 | D14: =B14*C14 -> 0.5
A15: =Referencias!B17 -> Embalagem Padrão | B15: 1 | C15: =Referencias!F17 -> 1.5 | D15: =B15*C15 -> 1.5
A16: Custo | D16: =SUM(D12:D15) -> 4.8
A17: Margem | B17: 0.55 | C17: =D16*B17 -> 2.64 | D17: =D16+C17 -> 7.44
A18: Pesquisa
A19: Valor | D19: 15
A21: Descanso de Panela em Croche Malha - Duplo | D21: 20
A22: =Referencias!B202 -> Fio de Malha Euroroma 140m | B22: 250 | C22: =Referencias!F202 -> 0.02 | D22: =B22*C22 -> 5
A23: =Referencias!B62 -> Frete | B23: 0 | C23: =Referencias!F62 -> 0 | D23: =B23*C23 -> 0
A24: =Referencias!B14 -> Desgaste Bloquinho/Outros | B24: 1 | C24: =Referencias!F14 -> 0.5 | D24: =B24*C24 -> 0.5
A25: =Referencias!B17 -> Embalagem Padrão | B25: 1 | C25: =Referencias!F17 -> 1.5 | D25: =B25*C25 -> 1.5
A26: Custo | D26: =SUM(D22:D25) -> 7
A27: Margem | B27: 0.55 | C27: =D26*B27 -> 3.85 | D27: =D26+C27 -> 10.85
A28: Pesquisa
A29: Valor | D29: 20
A31: Fralda com Crochê | D31: 15
A32: =Referencias!B147 -> Fralda Cremer 70x70 | B32: 1 | C32: =Referencias!F147 -> 7.18 | D32: =B32*C32 -> 7.18
A33: =Referencias!B7 -> Fio Clea 1000 160g | B33: 25 | C33: =Referencias!F7 -> 0.11 | D33: =B33*C33 -> 2.75
A34: =Referencias!B80 -> Linha Dinner | B34: 3.5 | C34: =Referencias!F80 -> 0.1 | D34: =B34*C34 -> 0.35
A35: =Referencias!B82 -> Papel Transfer | B35: 0.02 | C35: =Referencias!F82 -> 5.49 | D35: =B35*C35 -> 0.1098
A36: =Referencias!B83 -> Impressão A4 | B36: 0.02 | C36: =Referencias!F83 -> 0.5 | D36: =B36*C36 -> 0.01
A37: =Referencias!B62 -> Frete | C37: =Referencias!F62 -> 0 | D37: =B37*C37 -> 0
A38: =Referencias!B14 -> Desgaste Bloquinho/Outros | B38: 1 | C38: =Referencias!F14 -> 0.5 | D38: =B38*C38 -> 0.5
A39: =Referencias!B17 -> Embalagem Padrão | B39: 1 | C39: =Referencias!F17 -> 1.5 | D39: =B39*C39 -> 1.5
A40: Custo | D40: =SUM(D32:D39) -> 12.3998
A41: Margem | B41: 0.55 | C41: =D40*B41 -> 6.81989 | D41: =D40+C41 -> 19.21969
A42: Pesquisa
A43: Valor | D43: 15
...

Sheet Bebê
A1: Adesivo Garrafa 500ml - Com 60 | D1: 84
A2: =Referencias!B53 -> Papel fotografico A4 | B2: 9 | C2: =Referencias!F53 -> 0.8 | D2: =B2*C2 -> 7.2
A3: =Referencias!B22 -> Impressao Capa A4 | B3: 9 | C3: =Referencias!F22 -> 0.5 | D3: =B3*C3 -> 4.5
A4: =Referencias!B62 -> Frete | C4: =Referencias!F62 -> 0 | D4: =B4*C4 -> 0
A5: =Referencias!B14 -> Desgaste Bloquinho/Outros | B5: 1 | C5: =Referencias!F14 -> 0.5 | D5: =B5*C5 -> 0.5
A6: =Referencias!B17 -> Embalagem Padrão | B6: 1 | C6: =Referencias!F17 -> 1.5 | D6: =B6*C6 -> 1.5
A7: Custo | D7: =SUM(D2:D6) -> 13.7
A8: Margem | B8: 0.55 | C8: =D7*B8 -> 7.535 | D8: =D7+C8 -> 21.235
A9: Pesquisa | B9: elo7 | C9: elo7
A10: Valor | B10: 1.1 | C10: 1.9 | D10: 84
A12: Tag 4 x 4 com 150 | D12: 97
A13: =Referencias!B84 -> Papel 180gr A4 | B13: 5 | C13: =Referencias!F84 -> 0.32 | D13: =B13*C13 -> 1.6
A14: =Referencias!B22 -> Impressao Capa A4 | B14: 5 | C14: =Referencias!F22 -> 0.5 | D14: =B14*C14 -> 2.5
A15: =Referencias!B62 -> Frete | C15: =Referencias!F62 -> 0 | D15: =B15*C15 -> 0
A16: =Referencias!B14 -> Desgaste Bloquinho/Outros | B16: 1 | C16: =Referencias!F14 -> 0.5 | D16: =B16*C16 -> 0.5
A17: =Referencias!B17 -> Embalagem Padrão | B17: 1 | C17: =Referencias!F17 -> 1.5 | D17: =B17*C17 -> 1.5
A18: Custo | D18: =SUM(D13:D17) -> 6.1
A19: Margem | B19: 0.55 | C19: =D18*B19 -> 3.355 | D19: =D18+C19 -> 9.455
A20: Pesquisa | B20: elo7 | C20: elo7
A21: Valor | B21: 0.85 | C21: 0.63 | D21: 97
A23: Caderno de Assinaturas A4 Costurado | D23: 55
A24: =Referencias!B58 -> Papelão 16x22 | B24: 2 | C24: =Referencias!F58 -> 1.5 | D24: =B24*C24 -> 3
A25: =Referencias!B53 -> Papel fotografico A4 | B25: 2 | C25: =Referencias!F53 -> 0.8 | D25: =B25*C25 -> 1.6
A26: =Referencias!B31 -> bopp | B26: =0.3*2 -> 0.6 | C26: =Referencias!F31 -> 0.45 | D26: =B26*C26 -> 0.27
A27: =Referencias!B48 -> Papel guarda 15,5x21,5 offset adesivo | B27: 2 | C27: =Referencias!F48 -> 0.75 | D27: =B27*C27 -> 1.5
A28: =Referencias!B84 -> Papel 180gr A4 | B28: 30 | C28: =Referencias!F84 -> 0.32 | D28: =B28*C28 -> 9.6
A29: =Referencias!B121 -> Fita cetim | B29: 1.18 | C29: =Referencias!F121 -> 0.13 | D29: =B29*C29 -> 0.1534
A30: =Referencias!B10 -> Ilhos | B30: 10 | C30: =Referencias!F10 -> 0.05 | D30: =B30*C30 -> 0.5
A31: =Referencias!B22 -> Impressao Capa A4 | B31: 2 | C31: =Referencias!F22 -> 0.5 | D31: =B31*C31 -> 1
A32: =Referencias!B62 -> Frete | C32: =Referencias!F62 -> 0 | D32: =B32*C32 -> 0
A33: =Referencias!B15 -> Desgaste Caderno A5 | B33: 1 | C33: =Referencias!F15 -> 2 | D33: =B33*C33 -> 2
A34: =Referencias!B17 -> Embalagem Padrão | B34: 1 | C34: =Referencias!F17 -> 1.5 | D34: =B34*C34 -> 1.5
A35: Custo | D35: =SUM(D24:D34) -> 21.1234
A36: Margem | B36: 0.55 | C36: =D35*B36 -> 11.61787 | D36: =D35+C36 -> 32.74127
A37: Pesquisa | B37: praper
A38: Valor | B38: 84.9 | D38: 55
A40: Caderno A5 | D40: 45
A41: =Referencias!B58 -> Papelão 16x22 | B41: 2 | C41: =Referencias!F58 -> 1.5 | D41: =B41*C41 -> 3
A42: =Referencias!B53 -> Papel fotografico A4 | B42: 2 | C42: =Referencias!F53 -> 0.8 | D42: =B42*C42 -> 1.6
A43: =Referencias!B31 -> bopp | B43: =0.3*2 -> 0.6 | C43: =Referencias!F31 -> 0.45 | D43: =B43*C43 -> 0.27
...

Sheet Casamento
A1: Convite Padrinhos/Daminhas | E1: 42.5
A2: =Referencias!B37 -> miolo 180gr A4 | C2: 13 | D2: =Referencias!F37 -> 0.32 | E2: =C2*D2 -> 4.16
A3: =Referencias!B22 -> Impressao Capa A4 | C3: 13 | D3: =Referencias!F22 -> 0.5 | E3: =C3*D3 -> 6.5
A4: =Referencias!B62 -> Frete | D4: =Referencias!F62 -> 0 | E4: =C4*D4 -> 0
A5: =Referencias!B14 -> Desgaste Bloquinho/Outros | C5: 13 | D5: =Referencias!F14 -> 0.5 | E5: =C5*D5 -> 6.5
A6: =Referencias!B17 -> Embalagem Padrão | C6: 1 | D6: =Referencias!F17 -> 1.5 | E6: =C6*D6 -> 1.5
A7: Custo | E7: =SUM(E2:E6) -> 18.66
A8: Margem | C8: 0.55 | D8: =E7*C8 -> 10.263 | E8: =E7+D8 -> 28.923
A9: Pesquisa | D9: mp
A10: Valor | E10: 42.5
A12: Manual Padrinhos/Daminhas | E12: 42.5
A13: =Referencias!B37 -> miolo 180gr A4 | C13: 13 | D13: =Referencias!F37 -> 0.32 | E13: =C13*D13 -> 4.16
A14: =Referencias!B22 -> Impressao Capa A4 | C14: 13 | D14: =Referencias!F22 -> 0.5 | E14: =C14*D14 -> 6.5
A15: =Referencias!B121 -> Fita cetim | C15: =0.13*13 -> 1.69 | D15: =Referencias!F121 -> 0.13 | E15: =C15*D15 -> 0.2197
A16: =Referencias!B62 -> Frete | D16: =Referencias!F62 -> 0 | E16: =C16*D16 -> 0
A17: =Referencias!B14 -> Desgaste Bloquinho/Outros | C17: 13 | D17: =Referencias!F14 -> 0.5 | E17: =C17*D17 -> 6.5
A18: =Referencias!B17 -> Embalagem Padrão | C18: 1 | D18: =Referencias!F17 -> 1.5 | E18: =C18*D18 -> 1.5
A19: Custo | E19: =SUM(E13:E18) -> 18.8797
A20: Margem | C20: 0.55 | D20: =E19*C20 -> 10.383835 | E20: =E19+D20 -> 29.263535
A21: Pesquisa | D21: mp
A22: Valor | E22: 42.5
A24: Lágrimas | E24: 50
A25: =Referencias!B216 -> Sulfite 90gr A4 | C25: 5 | D25: =Referencias!F216 -> 0.1 | E25: =C25*D25 -> 0.5
A26: =Referencias!B22 -> Impressao Capa A4 | C26: 5 | D26: =Referencias!F22 -> 0.5 | E26: =C26*D26 -> 2.5
A27: =Referencias!B235 -> Lenço de Papel | C27: 40 | D27: =Referencias!F235 -> 0.2 | E27: =C27*D27 -> 8
A28: =Referencias!B234 -> Saco Adesivo Transparente 6x12cm | C28: 40 | D28: =Referencias!F234 -> 0.07 | E28: =C28*D28 -> 2.8
A29: =Referencias!B62 -> Frete | D29: =Referencias!F62 -> 0 | E29: =C29*D29 -> 0
A30: =Referencias!B14 -> Desgaste Bloquinho/Outros | C30: 1 | D30: =Referencias!F14 -> 0.5 | E30: =C30*D30 -> 0.5
A31: =Referencias!B17 -> Embalagem Padrão | C31: 1 | D31: =Referencias!F17 -> 1.5 | E31: =C31*D31 -> 1.5
A32: Custo | E32: =SUM(E25:E31) -> 15.8
A33: Margem | C33: 0.55 | D33: =E32*C33 -> 8.69 | E33: =E32+D33 -> 24.49
A34: Pesquisa | C34: 30 | D34: 50
A35: Valor | C35: 50 | D35: 80 | E35: 50
C36: =(D35+C35)/2 -> 65

Sheet Trevo Saúde
A1: Kit Higiene Bucal | D1: 9.5
A2: =Referencias!B75 -> Plástico Cristal 1mx1,4m | B2: 0.02 | C2: =Referencias!F75 -> 14.9 | D2: =B2*C2 -> 0.298
A3: =Referencias!B76 -> Tecido Tricoline 1mx1,4m trevo | B3: 0.06 | C3: =Referencias!F76 -> 33.8 | D3: =B3*C3 -> 2.028
A4: =Referencias!B77 -> Botão de Pressão | B4: 1 | C4: =Referencias!F77 -> 0.07 | D4: =B4*C4 -> 0.07
A5: =Referencias!B78 -> Manta R2 1mx1,4m | B5: 0.02 | C5: =Referencias!F78 -> 27.8 | D5: =B5*C5 -> 0.556
A6: =Referencias!B79 -> Vies 20m | B6: 0.8 | C6: =Referencias!F79 -> 0.32 | D6: =B6*C6 -> 0.256
A7: =Referencias!B80 -> Linha Dinner | B7: 3.16 | C7: =Referencias!F80 -> 0.1 | D7: =B7*C7 -> 0.316
A8: =Referencias!B81 -> Etiqueta Cetim 1,5 10m | B8: 0.1 | C8: =Referencias!F81 -> 0.25 | D8: =B8*C8 -> 0.025
A9: =Referencias!B82 -> Papel Transfer | B9: 0.02 | C9: =Referencias!F82 -> 5.49 | D9: =B9*C9 -> 0.1098
A10: =Referencias!B83 -> Impressão A4 | B10: 0.02 | C10: =Referencias!F83 -> 0.5 | D10: =B10*C10 -> 0.01
A11: =Referencias!B62 -> Frete | C11: =Referencias!F62 -> 0 | D11: =B11*C11 -> 0
A12: =Referencias!B14 -> Desgaste Bloquinho/Outros | B12: 1 | C12: =Referencias!F14 -> 0.5 | D12: =B12*C12 -> 0.5
A13: =Referencias!B17 -> Embalagem Padrão | B13: 1 | C13: =Referencias!F17 -> 1.5 | D13: =B13*C13 -> 1.5
A14: Custo | D14: =SUM(D2:D13) -> 5.6688
A15: Margem | B15: 0.55 | C15: =D14*B15 -> 3.11784 | D15: =D14+C15 -> 8.78664
A16: Pesquisa
A17: Valor | D17: 10
A19: Ecobag InvisaAlign | D19: 15
A20: =Referencias!B76 -> Tecido Tricoline 1mx1,4m trevo | B20: 0.22 | C20: =Referencias!F76 -> 33.8 | D20: =B20*C20 -> 7.436
A21: =Referencias!B80 -> Linha Dinner | B21: 7.6 | C21: =Referencias!F80 -> 0.1 | D21: =B21*C21 -> 0.76
A22: =Referencias!B81 -> Etiqueta Cetim 1,5 10m | B22: 0.1 | C22: =Referencias!F81 -> 0.25 | D22: =B22*C22 -> 0.025
A23: =Referencias!B82 -> Papel Transfer | B23: 0.02 | C23: =Referencias!F82 -> 5.49 | D23: =B23*C23 -> 0.1098
A24: =Referencias!B83 -> Impressão A4 | B24: 0.02 | C24: =Referencias!F83 -> 0.5 | D24: =B24*C24 -> 0.01
A25: =Referencias!B62 -> Frete | C25: =Referencias!F62 -> 0 | D25: =B25*C25 -> 0
A26: =Referencias!B14 -> Desgaste Bloquinho/Outros | B26: 1 | C26: =Referencias!F14 -> 0.5 | D26: =B26*C26 -> 0.5
A27: =Referencias!B17 -> Embalagem Padrão | B27: 1 | C27: =Referencias!F17 -> 1.5 | D27: =B27*C27 -> 1.5
A28: Custo | D28: =SUM(D20:D27) -> 10.3408
A29: Margem | B29: 0.55 | C29: =D28*B29 -> 5.68744 | D29: =D28+C29 -> 16.02824
A30: Pesquisa
A31: Valor | D31: 20
A33: Ecobag 30x40 | D33: 15
A34: =Referencias!B76 -> Tecido Tricoline 1mx1,4m trevo | B34: 0.38 | C34: 40 | D34: =B34*C34 -> 15.2
A35: =Referencias!B80 -> Linha Dinner | B35: 7.6 | C35: =Referencias!F80 -> 0.1 | D35: =B35*C35 -> 0.76
A36: =Referencias!B81 -> Etiqueta Cetim 1,5 10m | B36: 0.25 | C36: =Referencias!F81 -> 0.25 | D36: =B36*C36 -> 0.0625
A37: =Referencias!B82 -> Papel Transfer | B37: 0.02 | C37: =Referencias!F82 -> 5.49 | D37: =B37*C37 -> 0.1098
A38: =Referencias!B83 -> Impressão A4 | B38: 0.02 | C38: =Referencias!F83 -> 0.5 | D38: =B38*C38 -> 0.01
A39: =Referencias!B62 -> Frete | C39: =Referencias!F62 -> 0 | D39: =B39*C39 -> 0
A40: =Referencias!B14 -> Desgaste Bloquinho/Outros | B40: 1 | C40: =Referencias!F14 -> 0.5 | D40: =B40*C40 -> 0.5
A41: =Referencias!B17 -> Embalagem Padrão | B41: 1 | C41: =Referencias!F17 -> 1.5 | D41: =B41*C41 -> 1.5
A42: Custo | D42: =SUM(D34:D41) -> 18.1423
...

Sheet Fofurinhas
A1: Caderno A5 - Preguiça | D1: 50
A2: =Referencias!B58 -> Papelão 16x22 | B2: 2 | C2: =Referencias!F58 -> 1.5 | D2: =B2*C2 -> 3
A3: =Referencias!B53 -> Papel fotografico A4 | B3: 2 | C3: =Referencias!F53 -> 0.8 | D3: =B3*C3 -> 1.6
A4: =Referencias!B31 -> bopp | B4: =2*0.3 -> 0.6 | C4: =Referencias!F31 -> 0.45 | D4: =B4*C4 -> 0.27
A5: =Referencias!B48 -> Papel guarda 15,5x21,5 offset adesivo | B5: 2 | C5: =Referencias!F48 -> 0.75 | D5: =B5*C5 -> 1.5
A6: =Referencias!B45 -> miolo 90gr A5 | B6: 80 | C6: =Referencias!F45 -> 0.05 | D6: =B6*C6 -> 4
A7: =Referencias!B69 -> Espiral 20mm | B7: 1 | C7: =Referencias!F69 -> 0.64 | D7: =B7*C7 -> 0.64
A8: =Referencias!B22 -> Impressao Capa A4 | B8: 2 | C8: =Referencias!F22 -> 0.5 | D8: =B8*C8 -> 1
A9: =Referencias!B29 -> Impressao Miolo Frente Verso A5 | B9: 80 | C9: =Referencias!F29 -> 0.06 | D9: =B9*C9 -> 4.8
A10: =Referencias!B62 -> Frete | C10: =Referencias!F62 -> 0 | D10: =B10*C10 -> 0
A11: =Referencias!B15 -> Desgaste Caderno A5 | B11: 1 | C11: =Referencias!F15 -> 2 | D11: =B11*C11 -> 2
A12: =Referencias!B17 -> Embalagem Padrão | B12: 1 | C12: =Referencias!F17 -> 1.5 | D12: =B12*C12 -> 1.5
A13: Custo | D13: =SUM(D2:D12) -> 20.31
A14: Margem | B14: 0.55 | C14: =D13*B14 -> 11.1705 | D14: =D13+C14 -> 31.4805
A15: Pesquisa | B15: praper | C15: mp
A16: Valor | D16: 60
A18: Caderno A5 - Preguiça+ | D18: 75
A19: =Referencias!B58 -> Papelão 16x22 | B19: 2 | C19: =Referencias!F58 -> 1.5 | D19: =B19*C19 -> 3
A20: =Referencias!B53 -> Papel fotografico A4 | B20: 2 | C20: =Referencias!F53 -> 0.8 | D20: =B20*C20 -> 1.6
A21: =Referencias!B31 -> bopp | B21: =2*0.3 -> 0.6 | C21: =Referencias!F31 -> 0.45 | D21: =B21*C21 -> 0.27
A22: =Referencias!B48 -> Papel guarda 15,5x21,5 offset adesivo | B22: 2 | C22: =Referencias!F48 -> 0.75 | D22: =B22*C22 -> 1.5
A23: =Referencias!B45 -> miolo 90gr A5 | B23: 150 | C23: =Referencias!F45 -> 0.05 | D23: =B23*C23 -> 7.5
A24: =Referencias!B20 -> Espiral 33mm | B24: 1 | C24: =Referencias!F20 -> 4 | D24: =B24*C24 -> 4
A25: =Referencias!B22 -> Impressao Capa A4 | B25: 2 | C25: =Referencias!F22 -> 0.5 | D25: =B25*C25 -> 1
A26: =Referencias!B29 -> Impressao Miolo Frente Verso A5 | B26: 150 | C26: =Referencias!F29 -> 0.06 | D26: =B26*C26 -> 9
A27: =Referencias!B62 -> Frete | C27: =Referencias!F62 -> 0 | D27: =B27*C27 -> 0
A28: =Referencias!B15 -> Desgaste Caderno A5 | B28: 1 | C28: =Referencias!F15 -> 2 | D28: =B28*C28 -> 2
A29: =Referencias!B17 -> Embalagem Padrão | B29: 1 | C29: =Referencias!F17 -> 1.5 | D29: =B29*C29 -> 1.5
A30: Custo | D30: =SUM(D19:D29) -> 31.37
A31: Margem | B31: 0.55 | C31: =D30*B31 -> 17.2535 | D31: =D30+C31 -> 48.6235
A32: Pesquisa | B32: praper | C32: mp
A33: Valor | D33: 95
A35: Bloquinho de Anotações 12x12 cm - Preguiça | D35: 15
A36: =Referencias!B92 -> Papelão 12x12+12x12+12x1 | B36: 1 | C36: =Referencias!F92 -> 1.5 | D36: =B36*C36 -> 1.5
A37: =Referencias!B53 -> Papel fotografico A4 | B37: 1 | C37: =Referencias!F53 -> 0.8 | D37: =B37*C37 -> 0.8
A38: =Referencias!B31 -> bopp | B38: 0.3 | C38: =Referencias!F31 -> 0.45 | D38: =B38*C38 -> 0.135
A39: =Referencias!B66 -> Papel guarda offset adesivo A4 | B39: 1 | C39: =Referencias!F66 -> 0.75 | D39: =B39*C39 -> 0.75
A40: =Referencias!B68 -> miolo 75gr A7 | B40: 80 | C40: =Referencias!F68 -> 0.01 | D40: =B40*C40 -> 0.8
A41: =Referencias!B22 -> Impressao Capa A4 | B41: 1 | C41: =Referencias!F22 -> 0.5 | D41: =B41*C41 -> 0.5
A42: =Referencias!B62 -> Frete | C42: =Referencias!F62 -> 0 | D42: =B42*C42 -> 0
...

Sheet Costura Criativa
A1: Toalhinha para Lancheira 30x40 | D1: 15
A2: =Referencias!B76 -> Tecido Tricoline 1mx1,4m trevo | B2: 0.17 | C2: =Referencias!F76 -> 33.8 | D2: =B2*C2 -> 5.746
A3: =Referencias!B80 -> Linha Dinner | B3: 0.5 | C3: =Referencias!F80 -> 0.1 | D3: =B3*C3 -> 0.05
A4: =Referencias!B81 -> Etiqueta Cetim 1,5 10m | B4: 0.1 | C4: =Referencias!F81 -> 0.25 | D4: =B4*C4 -> 0.025
A5: =Referencias!B82 -> Papel Transfer | B5: 0.02 | C5: =Referencias!F82 -> 5.49 | D5: =B5*C5 -> 0.1098
A6: =Referencias!B83 -> Impressão A4 | B6: 0.02 | C6: =Referencias!F83 -> 0.5 | D6: =B6*C6 -> 0.01
A7: =Referencias!B62 -> Frete | C7: =Referencias!F62 -> 0 | D7: =B7*C7 -> 0
A8: =Referencias!B14 -> Desgaste Bloquinho/Outros | B8: 1 | C8: =Referencias!F14 -> 0.5 | D8: =B8*C8 -> 0.5
A9: =Referencias!B17 -> Embalagem Padrão | B9: 1 | C9: =Referencias!F17 -> 1.5 | D9: =B9*C9 -> 1.5
A10: Custo | D10: =SUM(D2:D9) -> 7.9408
A11: Margem | B11: 0.55 | C11: =D10*B11 -> 4.36744 | D11: =D10+C11 -> 12.30824
A12: Pesquisa
A13: Valor | D13: 15
A15: Capa Plástica para Caderneta de Vacina do Idoso | D15: 10
A16: =Referencias!B119 -> Plástico Alclear Light Translucido | B16: 0.1 | C16: =Referencias!F119 -> 26.9 | D16: =B16*C16 -> 2.69
A17: =Referencias!B79 -> Vies 20m | B17: 1.5 | C17: =Referencias!F79 -> 0.32 | D17: =B17*C17 -> 0.48
A18: =Referencias!B77 -> Botão de Pressão | B18: 2 | C18: =Referencias!F79 -> 0.32 | D18: =B18*C18 -> 0.64
A19: =Referencias!B80 -> Linha Dinner | B19: 3 | C19: =Referencias!F77 -> 0.07 | D19: =B19*C19 -> 0.21
A20: =Referencias!B62 -> Frete | C20: =Referencias!F62 -> 0 | D20: =B20*C20 -> 0
A21: =Referencias!B14 -> Desgaste Bloquinho/Outros | B21: 1 | C21: =Referencias!F14 -> 0.5 | D21: =B21*C21 -> 0.5
A22: =Referencias!B17 -> Embalagem Padrão | B22: 1 | C22: =Referencias!F17 -> 1.5 | D22: =B22*C22 -> 1.5
A23: Custo | D23: =SUM(D16:D22) -> 6.02
A24: Margem | B24: 0.55 | C24: =D23*B24 -> 3.311 | D24: =D23+C24 -> 9.331
A25: Pesquisa
A26: Valor | D26: 10
A28: Jogo 5 Marias | D28: 20
A29: =Referencias!B238 -> Tecido Tricoline 32cmx20cm | B29: 1 | C29: =Referencias!F238 -> 1.48 | D29: =B29*C29 -> 1.48
A30: =Referencias!B239 -> Tecido Tricoline 11cmx6cm | B30: 5 | C30: =Referencias!F239 -> 0.15 | D30: =B30*C30 -> 0.75
A31: =Referencias!B240 -> Barbante Bandeirantes nº 4 | B31: 1.5 | C31: =Referencias!F240 -> 0.02 | D31: =B31*C31 -> 0.03
A32: =Referencias!B241 -> Painço 500g | B32: 75 | C32: =Referencias!F241 -> 0.01 | D32: =B32*C32 -> 0.75
A33: =Referencias!B80 -> Linha Dinner | B33: 1.5 | C33: =Referencias!F80 -> 0.1 | D33: =B33*C33 -> 0.15
A34: =Referencias!B81 -> Etiqueta Cetim 1,5 10m | B34: 0.1 | C34: =Referencias!F81 -> 0.25 | D34: =B34*C34 -> 0.025
A35: =Referencias!B82 -> Papel Transfer | B35: 0.02 | C35: =Referencias!F82 -> 5.49 | D35: =B35*C35 -> 0.1098
A36: =Referencias!B83 -> Impressão A4 | B36: 0.02 | C36: =Referencias!F83 -> 0.5 | D36: =B36*C36 -> 0.01
A37: =Referencias!B37 -> miolo 180gr A4 | B37: 0.16 | C37: =Referencias!F37 -> 0.32 | D37: =B37*C37 -> 0.0512
A38: =Referencias!B28 -> Impressao Miolo Frente Verso A4 | B38: 0.16 | C38: =Referencias!F28 -> 0.12 | D38: =B38*C38 -> 0.0192
A39: =Referencias!B62 -> Frete | C39: =Referencias!F62 -> 0 | D39: =B39*C39 -> 0
A40: =Referencias!B14 -> Desgaste Bloquinho/Outros | B40: 1 | C40: =Referencias!F14 -> 0.5 | D40: =B40*C40 -> 0.5
A41: =Referencias!B17 -> Embalagem Padrão | B41: 1 | C41: =Referencias!F17 -> 1.5 | D41: =B41*C41 -> 1.5
A42: Custo | D42: =SUM(D29:D41) -> 5.3752
...

Sheet Sacolas em Papel
A1: Sacolinha P | D1: 6
A2: =Referencias!B84 -> Papel 180gr A4 | B2: 2 | C2: =Referencias!F84 -> 0.32 | D2: =B2*C2 -> 0.64
A3: =Referencias!B85 -> Alça - Fio Nautico circulo branco | B3: =0.26*2 -> 0.52 | C3: =Referencias!F85 -> 0.14 | D3: =B3*C3 -> 0.0728
A4: =Referencias!B83 -> Impressão A4 | B4: 2 | C4: =Referencias!F83 -> 0.5 | D4: =B4*C4 -> 1
A5: =Referencias!B62 -> Frete | C5: =Referencias!F62 -> 0 | D5: =B5*C5 -> 0
A6: =Referencias!B14 -> Desgaste Bloquinho/Outros | B6: 1 | C6: =Referencias!F14 -> 0.5 | D6: =B6*C6 -> 0.5
A7: =Referencias!B17 -> Embalagem Padrão | B7: 1 | C7: =Referencias!F17 -> 1.5 | D7: =B7*C7 -> 1.5
A8: Custo | D8: =SUM(D2:D7) -> 3.7128
A9: Margem | B9: 0.55 | C9: =D8*B9 -> 2.04204 | D9: =D8+C9 -> 5.75484
A10: Pesquisa
A11: Valor | D11: 6
A13: Sacolinha M | D13: 7
A14: =Referencias!B84 -> Papel 180gr A4 | B14: 3 | C14: =Referencias!F84 -> 0.32 | D14: =B14*C14 -> 0.96
A15: =Referencias!B85 -> Alça - Fio Nautico circulo branco | B15: =0.32*2 -> 0.64 | C15: =Referencias!F85 -> 0.14 | D15: =B15*C15 -> 0.0896
A16: =Referencias!B83 -> Impressão A4 | B16: 3 | C16: =Referencias!F83 -> 0.5 | D16: =B16*C16 -> 1.5
A17: =Referencias!B62 -> Frete | C17: =Referencias!F62 -> 0 | D17: =B17*C17 -> 0
A18: =Referencias!B14 -> Desgaste Bloquinho/Outros | B18: 1 | C18: =Referencias!F14 -> 0.5 | D18: =B18*C18 -> 0.5
A19: =Referencias!B17 -> Embalagem Padrão | B19: 1 | C19: =Referencias!F17 -> 1.5 | D19: =B19*C19 -> 1.5
A20: Custo | D20: =SUM(D14:D19) -> 4.5496
A21: Margem | B21: 0.55 | C21: =D20*B21 -> 2.50228 | D21: =D20+C21 -> 7.05188
A22: Pesquisa
A23: Valor | D23: 7
A25: Sacolinha 8,5 x 8,5 | D25: 5.5
A26: =Referencias!B84 -> Papel 180gr A4 | B26: 1 | C26: =Referencias!F84 -> 0.32 | D26: =B26*C26 -> 0.32
A27: =Referencias!B85 -> Alça - Fio Nautico circulo branco | B27: 0.51 | C27: =Referencias!F85 -> 0.14 | D27: =B27*C27 -> 0.0714
A28: =Referencias!B83 -> Impressão A4 | B28: 1 | C28: =Referencias!F83 -> 0.5 | D28: =B28*C28 -> 0.5
A29: =Referencias!B62 -> Frete | C29: =Referencias!F62 -> 0 | D29: =B29*C29 -> 0
A30: =Referencias!B13 -> Desgaste Agenda | B30: 1 | C30: =Referencias!F13 -> 1 | D30: =B30*C30 -> 1
A31: =Referencias!B17 -> Embalagem Padrão | B31: 1 | C31: =Referencias!F17 -> 1.5 | D31: =B31*C31 -> 1.5
A32: Custo | D32: =SUM(D26:D31) -> 3.3914
A33: Margem | B33: 0.55 | C33: =D32*B33 -> 1.86527 | D33: =D32+C33 -> 5.25667
A34: Pesquisa
A35: Valor | D35: 5.5
A37: Sacolinha M reciclado | D37: 8
A38: =Referencias!B86 -> Papel 180gr A4 Reciclado | B38: 3 | C38: =Referencias!F86 -> 0.25 | D38: =B38*C38 -> 0.75
A39: =Referencias!B87 -> Alça - Cordão de Algodão | B39: 0.51 | C39: =Referencias!F87 -> 0.52 | D39: =B39*C39 -> 0.2652
A40: =Referencias!B83 -> Impressão A4 | B40: 3 | C40: =Referencias!F83 -> 0.5 | D40: =B40*C40 -> 1.5
A41: =Referencias!B62 -> Frete | C41: =Referencias!F62 -> 0 | D41: =B41*C41 -> 0
A42: =Referencias!B13 -> Desgaste Agenda | B42: 1 | C42: =Referencias!F13 -> 1 | D42: =B42*C42 -> 1
A43: =Referencias!B17 -> Embalagem Padrão | B43: 1 | C43: =Referencias!F17 -> 1.5 | D43: =B43*C43 -> 1.5
...

Sheet Sacolas 60
A1: Sacolinha P | D1: 6
A2: =Referencias!B84 -> Papel 180gr A4 | B2: 120 | C2: =Referencias!F84 -> 0.32 | D2: =B2*C2 -> 38.4
A3: =Referencias!B85 -> Alça - Fio Nautico circulo branco | B3: =0.26*2*60 -> 31.2 | C3: =Referencias!F85 -> 0.14 | D3: =B3*C3 -> 4.368
A4: =Referencias!B83 -> Impressão A4 | B4: 120 | C4: =Referencias!F83 -> 0.5 | D4: =B4*C4 -> 60
A5: =Referencias!B62 -> Frete | C5: =Referencias!F62 -> 0 | D5: =B5*C5 -> 0
A6: =Referencias!B14 -> Desgaste Bloquinho/Outros | B6: 1 | C6: =Referencias!F14 -> 0.5 | D6: =B6*C6 -> 0.5
A7: =Referencias!B17 -> Embalagem Padrão | B7: 1 | C7: =Referencias!F17 -> 1.5 | D7: =B7*C7 -> 1.5
A8: Custo | D8: =SUM(D2:D7) -> 104.768
A9: Margem | B9: 0.55 | C9: =D8*B9 -> 57.6224 | D9: =D8+C9 -> 162.3904
A10: Pesquisa
A11: Valor | D11: 6
A13: Sacolinha M | D13: 7
A14: =Referencias!B84 -> Papel 180gr A4 | B14: 3 | C14: =Referencias!F84 -> 0.32 | D14: =B14*C14 -> 0.96
A15: =Referencias!B85 -> Alça - Fio Nautico circulo branco | B15: =0.32*2 -> 0.64 | C15: =Referencias!F85 -> 0.14 | D15: =B15*C15 -> 0.0896
A16: =Referencias!B83 -> Impressão A4 | B16: 3 | C16: =Referencias!F83 -> 0.5 | D16: =B16*C16 -> 1.5
A17: =Referencias!B62 -> Frete | C17: =Referencias!F62 -> 0 | D17: =B17*C17 -> 0
A18: =Referencias!B14 -> Desgaste Bloquinho/Outros | B18: 1 | C18: =Referencias!F14 -> 0.5 | D18: =B18*C18 -> 0.5
A19: =Referencias!B17 -> Embalagem Padrão | B19: 1 | C19: =Referencias!F17 -> 1.5 | D19: =B19*C19 -> 1.5
A20: Custo | D20: =SUM(D14:D19) -> 4.5496
A21: Margem | B21: 0.55 | C21: =D20*B21 -> 2.50228 | D21: =D20+C21 -> 7.05188
A22: Pesquisa
A23: Valor | D23: 7
A25: Sacolinha 8,5 x 8,5 | D25: 5.5
A26: =Referencias!B84 -> Papel 180gr A4 | B26: 1 | C26: =Referencias!F84 -> 0.32 | D26: =B26*C26 -> 0.32
A27: =Referencias!B85 -> Alça - Fio Nautico circulo branco | B27: 0.51 | C27: =Referencias!F85 -> 0.14 | D27: =B27*C27 -> 0.0714
A28: =Referencias!B83 -> Impressão A4 | B28: 1 | C28: =Referencias!F83 -> 0.5 | D28: =B28*C28 -> 0.5
A29: =Referencias!B62 -> Frete | C29: =Referencias!F62 -> 0 | D29: =B29*C29 -> 0
A30: =Referencias!B13 -> Desgaste Agenda | B30: 1 | C30: =Referencias!F13 -> 1 | D30: =B30*C30 -> 1
A31: =Referencias!B17 -> Embalagem Padrão | B31: 1 | C31: =Referencias!F17 -> 1.5 | D31: =B31*C31 -> 1.5
A32: Custo | D32: =SUM(D26:D31) -> 3.3914
A33: Margem | B33: 0.55 | C33: =D32*B33 -> 1.86527 | D33: =D32+C33 -> 5.25667
A34: Pesquisa
A35: Valor | D35: 5.5
A37: Sacolinha M reciclado | D37: 8
A38: =Referencias!B86 -> Papel 180gr A4 Reciclado | B38: 3 | C38: =Referencias!F86 -> 0.25 | D38: =B38*C38 -> 0.75
A39: =Referencias!B87 -> Alça - Cordão de Algodão | B39: 0.51 | C39: =Referencias!F87 -> 0.52 | D39: =B39*C39 -> 0.2652
A40: =Referencias!B83 -> Impressão A4 | B40: 3 | C40: =Referencias!F83 -> 0.5 | D40: =B40*C40 -> 1.5
A41: =Referencias!B62 -> Frete | C41: =Referencias!F62 -> 0 | D41: =B41*C41 -> 0
A42: =Referencias!B13 -> Desgaste Agenda | B42: 1 | C42: =Referencias!F13 -> 1 | D42: =B42*C42 -> 1
A43: =Referencias!B17 -> Embalagem Padrão | B43: 1 | C43: =Referencias!F17 -> 1.5 | D43: =B43*C43 -> 1.5
...

Sheet Sacolas 40
A1: Sacolinha P | D1: 6
A2: =Referencias!B84 -> Papel 180gr A4 | B2: 80 | C2: =Referencias!F84 -> 0.32 | D2: =B2*C2 -> 25.6
A3: =Referencias!B85 -> Alça - Fio Nautico circulo branco | B3: =0.26*2*40 -> 20.8 | C3: =Referencias!F85 -> 0.14 | D3: =B3*C3 -> 2.912
A4: =Referencias!B83 -> Impressão A4 | B4: 80 | C4: =Referencias!F83 -> 0.5 | D4: =B4*C4 -> 40
A5: =Referencias!B62 -> Frete | C5: =Referencias!F62 -> 0 | D5: =B5*C5 -> 0
A6: =Referencias!B14 -> Desgaste Bloquinho/Outros | B6: 40 | C6: =Referencias!F14 -> 0.5 | D6: =B6*C6 -> 20
A7: =Referencias!B17 -> Embalagem Padrão | B7: 1 | C7: =Referencias!F17 -> 1.5 | D7: =B7*C7 -> 1.5
A8: Custo | D8: =SUM(D2:D7) -> 90.012
A9: Margem | B9: 0.55 | C9: =D8*B9 -> 49.5066 | D9: =D8+C9 -> 139.5186
A10: Pesquisa
A11: Valor | D11: 125
A13: Sacolinha M | D13: 7
A14: =Referencias!B84 -> Papel 180gr A4 | B14: 120 | C14: =Referencias!F84 -> 0.32 | D14: =B14*C14 -> 38.4
A15: =Referencias!B85 -> Alça - Fio Nautico circulo branco | B15: =0.32*2*40 -> 25.6 | C15: =Referencias!F85 -> 0.14 | D15: =B15*C15 -> 3.584
A16: =Referencias!B83 -> Impressão A4 | B16: 120 | C16: =Referencias!F83 -> 0.5 | D16: =B16*C16 -> 60
A17: =Referencias!B62 -> Frete | C17: =Referencias!F62 -> 0 | D17: =B17*C17 -> 0
A18: =Referencias!B14 -> Desgaste Bloquinho/Outros | B18: 40 | C18: =Referencias!F14 -> 0.5 | D18: =B18*C18 -> 20
A19: =Referencias!B17 -> Embalagem Padrão | B19: 1 | C19: =Referencias!F17 -> 1.5 | D19: =B19*C19 -> 1.5
A20: Custo | D20: =SUM(D14:D19) -> 123.484
A21: Margem | B21: 0.55 | C21: =D20*B21 -> 67.9162 | D21: =D20+C21 -> 191.4002
A22: Pesquisa
A23: Valor | D23: 170
A25: Sacolinha 8,5 x 8,5 | D25: 5.5
A26: =Referencias!B84 -> Papel 180gr A4 | B26: 1 | C26: =Referencias!F84 -> 0.32 | D26: =B26*C26 -> 0.32
A27: =Referencias!B85 -> Alça - Fio Nautico circulo branco | B27: 0.51 | C27: =Referencias!F85 -> 0.14 | D27: =B27*C27 -> 0.0714
A28: =Referencias!B83 -> Impressão A4 | B28: 1 | C28: =Referencias!F83 -> 0.5 | D28: =B28*C28 -> 0.5
A29: =Referencias!B62 -> Frete | C29: =Referencias!F62 -> 0 | D29: =B29*C29 -> 0
A30: =Referencias!B13 -> Desgaste Agenda | B30: 1 | C30: =Referencias!F13 -> 1 | D30: =B30*C30 -> 1
A31: =Referencias!B17 -> Embalagem Padrão | B31: 1 | C31: =Referencias!F17 -> 1.5 | D31: =B31*C31 -> 1.5
A32: Custo | D32: =SUM(D26:D31) -> 3.3914
A33: Margem | B33: 0.55 | C33: =D32*B33 -> 1.86527 | D33: =D32+C33 -> 5.25667
A34: Pesquisa
A35: Valor | D35: 5.5
A37: Sacolinha M reciclado | D37: 8
A38: =Referencias!B86 -> Papel 180gr A4 Reciclado | B38: 3 | C38: =Referencias!F86 -> 0.25 | D38: =B38*C38 -> 0.75
A39: =Referencias!B87 -> Alça - Cordão de Algodão | B39: 0.51 | C39: =Referencias!F87 -> 0.52 | D39: =B39*C39 -> 0.2652
A40: =Referencias!B83 -> Impressão A4 | B40: 3 | C40: =Referencias!F83 -> 0.5 | D40: =B40*C40 -> 1.5
A41: =Referencias!B62 -> Frete | C41: =Referencias!F62 -> 0 | D41: =B41*C41 -> 0
A42: =Referencias!B13 -> Desgaste Agenda | B42: 1 | C42: =Referencias!F13 -> 1 | D42: =B42*C42 -> 1
A43: =Referencias!B17 -> Embalagem Padrão | B43: 1 | C43: =Referencias!F17 -> 1.5 | D43: =B43*C43 -> 1.5
...

Sheet Arraiá24
A1: Mini Chapéu em Crochê | D1: 15
A2: =Referencias!B200 -> Lã Balloon 100g | B2: 20 | C2: =Referencias!F200 -> 0.17 | D2: =B2*C2 -> 3.4
A3: =Referencias!B201 -> Bico de Pato Jacaré com Garra | B3: 1 | C3: =Referencias!F201 -> 0.78 | D3: =B3*C3 -> 0.78
A4: =Referencias!B62 -> Frete | C4: =Referencias!F62 -> 0 | D4: =B4*C4 -> 0
A5: =Referencias!B14 -> Desgaste Bloquinho/Outros | B5: 1 | C5: =Referencias!F14 -> 0.5 | D5: =B5*C5 -> 0.5
A6: =Referencias!B17 -> Embalagem Padrão | B6: 1 | C6: =Referencias!F17 -> 1.5 | D6: =B6*C6 -> 1.5
A7: Custo | D7: =SUM(D2:D6) -> 6.18
A8: Margem | B8: 0.55 | C8: =D7*B8 -> 3.399 | D8: =D7+C8 -> 9.579
A9: Pesquisa | B9: praper | C9: mp
A10: Valor | B10: 10 | C10: 15 | D10: 15
A12: Descanso de Panela em Croche Malha - Quadrado | D12: 15
A13: =Referencias!B202 -> Fio de Malha Euroroma 140m | B13: 140 | C13: =Referencias!F202 -> 0.02 | D13: =B13*C13 -> 2.8
A14: =Referencias!B62 -> Frete | C14: =Referencias!F62 -> 0 | D14: =B14*C14 -> 0
A15: =Referencias!B14 -> Desgaste Bloquinho/Outros | B15: 1 | C15: =Referencias!F14 -> 0.5 | D15: =B15*C15 -> 0.5
A16: =Referencias!B17 -> Embalagem Padrão | B16: 1 | C16: =Referencias!F17 -> 1.5 | D16: =B16*C16 -> 1.5
A17: Custo | D17: =SUM(D13:D16) -> 4.8
A18: Margem | B18: 0.55 | C18: =D17*B18 -> 2.64 | D18: =D17+C18 -> 7.44
A19: Pesquisa
A20: Valor | D20: 15
A22: Descanso de Panela em Croche Malha - Flor | D22: 15
A23: =Referencias!B202 -> Fio de Malha Euroroma 140m | B23: 140 | C23: =Referencias!F202 -> 0.02 | D23: =B23*C23 -> 2.8
A24: =Referencias!B62 -> Frete | C24: =Referencias!F62 -> 0 | D24: =B24*C24 -> 0
A25: =Referencias!B14 -> Desgaste Bloquinho/Outros | B25: 1 | C25: =Referencias!F14 -> 0.5 | D25: =B25*C25 -> 0.5
A26: =Referencias!B17 -> Embalagem Padrão | B26: 1 | C26: =Referencias!F17 -> 1.5 | D26: =B26*C26 -> 1.5
A27: Custo | D27: =SUM(D23:D26) -> 4.8
A28: Margem | B28: 0.55 | C28: =D27*B28 -> 2.64 | D28: =D27+C28 -> 7.44
A29: Pesquisa
A30: Valor | D30: 15
A32: Descanso de Panela em Croche Malha - Duplo | D32: 20
A33: =Referencias!B202 -> Fio de Malha Euroroma 140m | B33: 250 | C33: =Referencias!F202 -> 0.02 | D33: =B33*C33 -> 5
A34: =Referencias!B62 -> Frete | B34: 0 | C34: =Referencias!F62 -> 0 | D34: =B34*C34 -> 0
A35: =Referencias!B14 -> Desgaste Bloquinho/Outros | B35: 1 | C35: =Referencias!F14 -> 0.5 | D35: =B35*C35 -> 0.5
A36: =Referencias!B17 -> Embalagem Padrão | B36: 1 | C36: =Referencias!F17 -> 1.5 | D36: =B36*C36 -> 1.5
A37: Custo | D37: =SUM(D33:D36) -> 7
A38: Margem | B38: 0.55 | C38: =D37*B38 -> 3.85 | D38: =D37+C38 -> 10.85
A39: Pesquisa
A40: Valor | D40: 20

Sheet Mães24
A1: Caderno de Receitas | D1: 45
A2: =Referencias!B58 -> Papelão 16x22 | B2: 2 | C2: =Referencias!F58 -> 1.5 | D2: =B2*C2 -> 3
A3: =Referencias!B53 -> Papel fotografico A4 | B3: 2 | C3: =Referencias!F53 -> 0.8 | D3: =B3*C3 -> 1.6
A4: =Referencias!B31 -> bopp | B4: =2*0.3 -> 0.6 | C4: =Referencias!F31 -> 0.45 | D4: =B4*C4 -> 0.27
A5: =Referencias!B48 -> Papel guarda 15,5x21,5 offset adesivo | B5: 2 | C5: =Referencias!F48 -> 0.75 | D5: =B5*C5 -> 1.5
A6: =Referencias!B45 -> miolo 90gr A5 | B6: 102 | C6: =Referencias!F45 -> 0.05 | D6: =B6*C6 -> 5.1
A7: =Referencias!B19 -> Espiral 29mm | B7: 1 | C7: =Referencias!F19 -> 1.83 | D7: =B7*C7 -> 1.83
A8: =Referencias!B22 -> Impressao Capa A4 | B8: 2 | C8: =Referencias!F22 -> 0.5 | D8: =B8*C8 -> 1
A9: =Referencias!B29 -> Impressao Miolo Frente Verso A5 | B9: 102 | C9: =Referencias!F29 -> 0.06 | D9: =B9*C9 -> 6.12
A10: =Referencias!B62 -> Frete | C10: =Referencias!F62 -> 0 | D10: =B10*C10 -> 0
A11: =Referencias!B15 -> Desgaste Caderno A5 | B11: 1 | C11: =Referencias!F15 -> 2 | D11: =B11*C11 -> 2
A12: =Referencias!B17 -> Embalagem Padrão | B12: 1 | C12: =Referencias!F17 -> 1.5 | D12: =B12*C12 -> 1.5
A13: Custo | D13: =SUM(D2:D12) -> 23.92
A14: Margem | B14: 0.55 | C14: =D13*B14 -> 13.156 | D14: =D13+C14 -> 37.076
A15: Pesquisa | B15: praper | C15: mp
A16: Valor | D16: 50
A18: Terço Aparecida P | D18: 20
A19: =Referencias!B165 -> Entermeio Nossa Senhora Aparecida 1,5x1,1 | B19: 1 | C19: =Referencias!F165 -> 0.97 | D19: =B19*C19 -> 0.97
A20: =Referencias!B168 -> Cruxifixo Metal Niquel | B20: 1 | C20: =Referencias!F168 -> 0.85 | D20: =B20*C20 -> 0.85
A21: =Referencias!B161 -> Miçanga Jablonex | B21: 3 | C21: =Referencias!F161 -> 0.47 | D21: =B21*C21 -> 1.41
A22: =Referencias!B172 -> Argola | B22: 1 | C22: =Referencias!F172 -> 0.14 | D22: =B22*C22 -> 0.14
A23: =Referencias!B170 -> Contrapino | B23: 59 | C23: =Referencias!F170 -> 0.02 | D23: =B23*C23 -> 1.18
A24: =Referencias!B173 -> Caixa Acrilica 5x5 | B24: 1 | C24: =Referencias!F173 -> 1 | D24: =B24*C24 -> 1
A25: =Referencias!B174 -> Feltro 10x5 | B25: 1 | C25: =Referencias!F174 -> 0.13 | D25: =B25*C25 -> 0.13
A26: =Referencias!B9 -> Fita cetim | B26: 0.15 | C26: =Referencias!F9 -> 0.13 | D26: =B26*C26 -> 0.0195
A27: =Referencias!B62 -> Frete | C27: =Referencias!F62 -> 0 | D27: =B27*C27 -> 0
A28: =Referencias!B14 -> Desgaste Bloquinho/Outros | B28: 1 | C28: =Referencias!F14 -> 0.5 | D28: =B28*C28 -> 0.5
A29: =Referencias!B17 -> Embalagem Padrão | B29: 1 | C29: =Referencias!F17 -> 1.5 | D29: =B29*C29 -> 1.5
A30: Custo | D30: =SUM(D19:D29) -> 7.6995
A31: Margem | B31: 0.55 | C31: =D30*B31 -> 4.234725 | D31: =D30+C31 -> 11.934225
A32: Pesquisa
A33: Valor | D33: 20
A35: Terço Aparecida M | D35: 30
A36: =Referencias!B164 -> Entermeio Nossa Senhora Aparecida 1,9x1,5 | B36: 1 | C36: =Referencias!F164 -> 1.74 | D36: =B36*C36 -> 1.74
A37: =Referencias!B169 -> Cruz Face de Cristo 3,3x2 | B37: 1 | C37: =Referencias!F169 -> 1.2 | D37: =B37*C37 -> 1.2
A38: =Referencias!B160 -> Balão de acrilico | B38: 6 | C38: =Referencias!F160 -> 0.16 | D38: =B38*C38 -> 0.96
A39: =Referencias!B163 -> Conta Plastica Florzinha | B39: 1 | C39: =Referencias!F163 -> 0.19 | D39: =B39*C39 -> 0.19
A40: =Referencias!B172 -> Argola | B40: 1 | C40: =Referencias!F172 -> 0.14 | D40: =B40*C40 -> 0.14
A41: =Referencias!B170 -> Contrapino | B41: 59 | C41: =Referencias!F170 -> 0.02 | D41: =B41*C41 -> 1.18
A42: =Referencias!B173 -> Caixa Acrilica 5x5 | B42: 1 | C42: =Referencias!F173 -> 1 | D42: =B42*C42 -> 1
...

Sheet Pascoa24
A1: Caça aos ovos | D1: 15
A2: =Referencias!B37 -> miolo 180gr A4 | B2: 5 | C2: =Referencias!F37 -> 0.32 | D2: =B2*C2 -> 1.6
A3: =Referencias!B22 -> Impressao Capa A4 | B3: 5 | C3: =Referencias!F22 -> 0.5 | D3: =B3*C3 -> 2.5
A4: =Referencias!B62 -> Frete | C4: =Referencias!F62 -> 0 | D4: =B4*C4 -> 0
A5: =Referencias!B14 -> Desgaste Bloquinho/Outros | B5: 1 | C5: =Referencias!F14 -> 0.5 | D5: =B5*C5 -> 0.5
A6: =Referencias!B17 -> Embalagem Padrão | B6: 1 | C6: =Referencias!F17 -> 1.5 | D6: =B6*C6 -> 1.5
A7: Custo | D7: =SUM(D2:D6) -> 6.1
A8: Margem | B8: 0.55 | C8: =D7*B8 -> 3.355 | D8: =D7+C8 -> 9.455
A9: Pesquisa
A10: Valor | D10: 20
A12: Sacolinha P | D12: 5.5
A13: =Referencias!B84 -> Papel 180gr A4 | B13: 2 | C13: =Referencias!F84 -> 0.32 | D13: =B13*C13 -> 0.64
A14: =Referencias!B85 -> Alça - Fio Nautico circulo branco | B14: 0.52 | C14: =Referencias!F85 -> 0.14 | D14: =B14*C14 -> 0.0728
A15: =Referencias!B83 -> Impressão A4 | B15: 2 | C15: =Referencias!F83 -> 0.5 | D15: =B15*C15 -> 1
A16: =Referencias!B62 -> Frete | C16: =Referencias!F62 -> 0 | D16: =B16*C16 -> 0
A17: =Referencias!B14 -> Desgaste Bloquinho/Outros | B17: 1 | C17: =Referencias!F14 -> 0.5 | D17: =B17*C17 -> 0.5
A18: =Referencias!B17 -> Embalagem Padrão | B18: 1 | C18: =Referencias!F17 -> 1.5 | D18: =B18*C18 -> 1.5
A19: Custo | D19: =SUM(D13:D18) -> 3.7128
A20: Margem | B20: 0.55 | C20: =D19*B20 -> 2.04204 | D20: =D19+C20 -> 5.75484
A21: Pesquisa
A22: Valor | D22: 6
A24: Sacolinha G | D24: 6.5
A25: =Referencias!B84 -> Papel 180gr A4 | B25: 3 | C25: =Referencias!F84 -> 0.32 | D25: =B25*C25 -> 0.96
A26: =Referencias!B85 -> Alça - Fio Nautico circulo branco | B26: 0.64 | C26: =Referencias!F85 -> 0.14 | D26: =B26*C26 -> 0.0896
A27: =Referencias!B83 -> Impressão A4 | B27: 3 | C27: =Referencias!F83 -> 0.5 | D27: =B27*C27 -> 1.5
A28: =Referencias!B62 -> Frete | B28: 0 | C28: =Referencias!F62 -> 0 | D28: =B28*C28 -> 0
A29: =Referencias!B14 -> Desgaste Bloquinho/Outros | B29: 1 | C29: =Referencias!F14 -> 0.5 | D29: =B29*C29 -> 0.5
A30: =Referencias!B17 -> Embalagem Padrão | B30: 1 | C30: =Referencias!F17 -> 1.5 | D30: =B30*C30 -> 1.5
A31: Custo | D31: =SUM(D25:D30) -> 4.5496
A32: Margem | B32: 0.55 | C32: =D31*B32 -> 2.50228 | D32: =D31+C32 -> 7.05188
A33: Pesquisa
A34: Valor | D34: 7.5
A36: Saquinho bom bom | D36: 4
A37: =Referencias!B100 -> Papel 180gr A6 | B37: 1 | C37: =Referencias!F100 -> 0.08 | D37: =B37*C37 -> 0.08
A38: =Referencias!B114 -> Sonho de Valsa 15g | B38: 1 | C38: =Referencias!F114 -> 1.17 | D38: =B38*C38 -> 1.17
A39: =Referencias!B24 -> Impressao Capa A6 | B39: 1 | C39: =Referencias!F24 -> 0.13 | D39: =B39*C39 -> 0.13
A40: =Referencias!B9 -> Fita cetim | B40: 0.15 | C40: =Referencias!F9 -> 0.13 | D40: =B40*C40 -> 0.0195
A41: =Referencias!B62 -> Frete | C41: =Referencias!F62 -> 0 | D41: =B41*C41 -> 0
A42: =Referencias!B14 -> Desgaste Bloquinho/Outros | B42: 1 | C42: =Referencias!F14 -> 0.5 | D42: =B42*C42 -> 0.5
A43: =Referencias!B107 -> Embalagem Atacado | B43: 1 | C43: =Referencias!F107 -> 0.5 | D43: =B43*C43 -> 0.5
...

Sheet Mulher24
A1: Chá Personalizado | D1: 4.6
A2: =Referencias!B153 -> Chá Twinings Frutas Silvestres | B2: 1 | C2: =Referencias!F153 -> 1.69 | D2: =B2*C2 -> 1.69
A3: =Referencias!B111 -> Card OffSet 180gr | B3: 1 | C3: =Referencias!F111 -> 0.05 | D3: =B3*C3 -> 0.05
A4: =Referencias!B23 -> Impressao Capa A5 | B4: 1 | C4: =Referencias!F23 -> 0.25 | D4: =B4*C4 -> 0.25
A5: =Referencias!B62 -> Frete | C5: =Referencias!F62 -> 0 | D5: =B5*C5 -> 0
A6: =Referencias!B14 -> Desgaste Bloquinho/Outros | B6: 1 | C6: =Referencias!F14 -> 0.5 | D6: =B6*C6 -> 0.5
A7: =Referencias!B107 -> Embalagem Atacado | B7: 1 | C7: =Referencias!F107 -> 0.5 | D7: =B7*C7 -> 0.5
A8: Custo | D8: =SUM(D2:D7) -> 2.99
